<?xml version="1.0"?>
<robot xmlns:xacro="http://www.ros.org/wiki/xacro" name="go2">
    <link name="base_link">
        <visual>
            <geometry>
                <box size="0.4 0.2 0.1"/>
            </geometry>
        </visual>
    </link>

    <link name="front_left_leg">
        <visual>
            <geometry>
                <box size="0.4 0.2 0.1"/>
            </geometry>
        </visual>
    </link>
    <joint name="front_left_leg_joint" type="continuous">
        <parent link="base_link"/>
        <child link="front_left_leg"/>
        <origin xyz="0.2 0.1 0" rpy="0 0 0"/>
    </joint>
</robot>